Workbook

Sheet Cases
A1: Player | B1: Position | C1: Year left | D1: Destination club | E1: Operation type | F1: Initial fee (€M) | G1: Retained rights (%) | H1: Buy-back | I1: Right of first refusal | J1: Sell-on (%) | K1: Bought back | L1: Buy-back cost (€M) | M1: Direct net income (€M) | N1: Optionality index | O1: Contractual detail | P1: Primary source | Q1: Confidence
A2: Roberto Soldado | B2: Forward | C2: 2008 | D2: Getafe | E2: Transfer | F2: 6 | H2: Yes | I2: No | K2: No | M2: =F2-IF(K2="Yes",IF(L2="",0,L2),0) -> 6 | N2: =IF(G2>0,1,0)+IF(H2="Yes",1,0)+IF(I2="Yes",1,0)+IF(J2>0,1,0) -> 1 | O2: Amount reported as up to €6M | P2: https://www.uefa.com/news-media/news/01cf-0f84e103e15d-07b4863d3d03-1000--soldado-set-to-seal-getafe-switch/ | Q2: Medium
A3: Javi García | B3: Midfielder | C3: 2009 | D3: Benfica | E3: Transfer | F3: 7 | H3: No | I3: No | K3: No | M3: =F3-IF(K3="Yes",IF(L3="",0,L3),0) -> 7 | N3: =IF(G3>0,1,0)+IF(H3="Yes",1,0)+IF(I3="Yes",1,0)+IF(J3>0,1,0) -> 0 | O3: Outright sale | P3: https://as.com/futbol/2009/07/27/mas_futbol/1248645630_850215.html | Q3: Medium
A4: Álvaro Negredo | B4: Forward | C4: 2009 | D4: Almería / Sevilla | E4: Sale with buy-back | F4: 15 | H4: Yes | I4: No | K4: Yes | L4: 5 | M4: =F4-IF(K4="Yes",IF(L4="",0,L4),0) -> 10 | N4: =IF(G4>0,1,0)+IF(H4="Yes",1,0)+IF(I4="Yes",1,0)+IF(J4>0,1,0) -> 1 | O4: Madrid exercised the buy-back before selling to Sevilla | P4: https://www.relevo.com/futbol/liga-primera/formula-cedidos-funciona-ventas-recompra-20221223100551-nt.html | Q4: Medium
A5: Esteban Granero | B5: Midfielder | C5: 2008 | D5: Getafe | E5: Sale with buy-back | F5: 3 | H5: Yes | I5: No | K5: Yes | L5: 4 | M5: =F5-IF(K5="Yes",IF(L5="",0,L5),0) -> -1 | N5: =IF(G5>0,1,0)+IF(H5="Yes",1,0)+IF(I5="Yes",1,0)+IF(J5>0,1,0) -> 1 | O5: Bought back a year later | P5: https://www.skysports.com/football/news/3814810/getafe-sign-granero | Q5: Medium
A6: Dani Parejo | B6: Midfielder | C6: 2009 | D6: Getafe | E6: Sale with buy-back | F6: 3 | H6: Yes | I6: No | K6: No | M6: =F6-IF(K6="Yes",IF(L6="",0,L6),0) -> 3 | N6: =IF(G6>0,1,0)+IF(H6="Yes",1,0)+IF(I6="Yes",1,0)+IF(J6>0,1,0) -> 1 | O6: Future control rights reported | P6: https://www.relevo.com/futbol/liga-primera/formula-cedidos-funciona-ventas-recompra-20221223100551-nt.html | Q6: Low
A7: Borja Valero | B7: Midfielder | C7: 2007 | D7: Mallorca | E7: Transfer | F7: 0 | H7: No | I7: No | K7: No | M7: =F7-IF(K7="Yes",IF(L7="",0,L7),0) -> 0 | N7: =IF(G7>0,1,0)+IF(H7="Yes",1,0)+IF(I7="Yes",1,0)+IF(J7>0,1,0) -> 0 | O7: Departure with no significant public fee | P7: https://www.transfermarkt.com/borja-valero/transfers/spieler/40372 | Q7: Low
A8: Juan Mata | B8: Attacking midfielder | C8: 2007 | D8: Valencia | E8: End of contract | F8: 0 | H8: No | I8: No | K8: No | M8: =F8-IF(K8="Yes",IF(L8="",0,L8),0) -> 0 | N8: =IF(G8>0,1,0)+IF(H8="Yes",1,0)+IF(I8="Yes",1,0)+IF(J8>0,1,0) -> 0 | O8: Free departure after not renewing | P8: https://www.transfermarkt.com/juan-mata/transfers/spieler/44068 | Q8: Medium
A9: José Callejón | B9: Winger | C9: 2008 | D9: Espanyol | E9: Transfer | F9: 1.2 | H9: Yes | I9: No | K9: Yes | L9: 5 | M9: =F9-IF(K9="Yes",IF(L9="",0,L9),0) -> -3.8 | N9: =IF(G9>0,1,0)+IF(H9="Yes",1,0)+IF(I9="Yes",1,0)+IF(J9>0,1,0) -> 1 | O9: Bought back in 2011 | P9: https://www.transfermarkt.com/jose-callejon/transfers/spieler/25927 | Q9: Medium
A10: Dani Carvajal | B10: Right-back | C10: 2012 | D10: Bayer Leverkusen | E10: Sale with buy-back | F10: 5 | H10: Yes | I10: No | K10: Yes | L10: 6.5 | M10: =F10-IF(K10="Yes",IF(L10="",0,L10),0) -> -1.5 | N10: =IF(G10>0,1,0)+IF(H10="Yes",1,0)+IF(I10="Yes",1,0)+IF(J10>0,1,0) -> 1 | O10: Three buy-back windows; returned the following year | P10: https://www.uefa.com/uefachampionsleague/news/0250-0c5101575c8f-e8cc021f4c61-1000--carvajal-returns-to-madrid-from-leverkusen/ | Q10: High
A11: Pablo Sarabia | B11: Attacking midfielder | C11: 2011 | D11: Getafe | E11: Transfer | F11: 3 | H11: Yes | I11: No | K11: No | M11: =F11-IF(K11="Yes",IF(L11="",0,L11),0) -> 3 | N11: =IF(G11>0,1,0)+IF(H11="Yes",1,0)+IF(I11="Yes",1,0)+IF(J11>0,1,0) -> 1 | O11: Buy-back clause reported | P11: https://www.transfermarkt.com/pablo-sarabia/transfers/spieler/74230 | Q11: Low
A12: Joselu Mato | B12: Forward | C12: 2012 | D12: Hoffenheim | E12: Transfer | F12: 6 | H12: No | I12: No | K12: No | M12: =F12-IF(K12="Yes",IF(L12="",0,L12),0) -> 6 | N12: =IF(G12>0,1,0)+IF(H12="Yes",1,0)+IF(I12="Yes",1,0)+IF(J12>0,1,0) -> 0 | O12: Outright sale; returned years later on loan from another club | P12: https://www.transfermarkt.com/joselu/transfers/spieler/81999 | Q12: Medium
A13: Álvaro Morata | B13: Forward | C13: 2014 | D13: Juventus | E13: Sale with buy-back | F13: 20 | H13: Yes | I13: No | K13: Yes | L13: 30 | M13: =F13-IF(K13="Yes",IF(L13="",0,L13),0) -> -10 | N13: =IF(G13>0,1,0)+IF(H13="Yes",1,0)+IF(I13="Yes",1,0)+IF(J13>0,1,0) -> 1 | O13: Bought back in 2016; later sold to Chelsea | P13: https://www.nbcsports.com/soccer/news/alvaro-morata-joins-juventus-from-real-madrid | Q13: High
A14: Jesé Rodríguez | B14: Winger | C14: 2016 | D14: PSG | E14: Transfer | F14: 25 | H14: No | I14: No | K14: No | M14: =F14-IF(K14="Yes",IF(L14="",0,L14),0) -> 25 | N14: =IF(G14>0,1,0)+IF(H14="Yes",1,0)+IF(I14="Yes",1,0)+IF(J14>0,1,0) -> 0 | O14: Outright sale reported at around €25M | P14: https://www.rtve.es/deportes/20160808/real-madrid-hace-oficial-traspaso-jese-rodriguez-psg/1380841.shtml | Q14: High
A15: Mariano Díaz | B15: Forward | C15: 2017 | D15: Olympique Lyon | E15: Sale with sell-on | F15: 8 | H15: No | I15: Yes | J15: 35 | K15: Yes | L15: 22 | M15: =F15-IF(K15="Yes",IF(L15="",0,L15),0) -> -14 | N15: =IF(G15>0,1,0)+IF(H15="Yes",1,0)+IF(I15="Yes",1,0)+IF(J15>0,1,0) -> 2 | O15: 35% retained and right of first refusal; returned in 2018 | P15: https://en.as.com/en/2018/08/29/soccer/1535566126_578615.html | Q15: High
A16: Marcos Llorente | B16: Midfielder | C16: 2019 | D16: Atlético de Madrid | E16: Transfer | F16: 30 | H16: No | I16: No | K16: No | M16: =F16-IF(K16="Yes",IF(L16="",0,L16),0) -> 30 | N16: =IF(G16>0,1,0)+IF(H16="Yes",1,0)+IF(I16="Yes",1,0)+IF(J16>0,1,0) -> 0 | O16: Official statement; fee reported by the press | P16: https://www.realmadrid.com/es-ES/noticias/club/comunicados/comunicado-oficial-marcos-llorente-20-06-2019 | Q16: High
A17: Raúl de Tomás | B17: Forward | C17: 2019 | D17: Benfica | E17: Transfer | F17: 20 | H17: No | I17: No | K17: No | M17: =F17-IF(K17="Yes",IF(L17="",0,L17),0) -> 20 | N17: =IF(G17>0,1,0)+IF(H17="Yes",1,0)+IF(I17="Yes",1,0)+IF(J17>0,1,0) -> 0 | O17: Outright sale | P17: https://www.transfermarkt.com/raul-de-tomas/transfers/spieler/206968 | Q17: Medium
A18: Achraf Hakimi | B18: Right-back | C18: 2020 | D18: Inter de Milán | E18: Transfer | F18: 40 | H18: No | I18: Yes | K18: No | M18: =F18-IF(K18="Yes",IF(L18="",0,L18),0) -> 40 | N18: =IF(G18>0,1,0)+IF(H18="Yes",1,0)+IF(I18="Yes",1,0)+IF(J18>0,1,0) -> 1 | O18: Base fee close to €40M; right of first refusal reported | P18: https://uk.investing.com/news/general/inter-reach-agreement-to-sign-hakimi-from-real-madrid-2154298 | Q18: High
A19: Sergio Reguilón | B19: Left-back | C19: 2020 | D19: Tottenham | E19: Sale with buy-back | F19: 30 | H19: Yes | I19: Yes | K19: No | M19: =F19-IF(K19="Yes",IF(L19="",0,L19),0) -> 30 | N19: =IF(G19>0,1,0)+IF(H19="Yes",1,0)+IF(I19="Yes",1,0)+IF(J19>0,1,0) -> 2 | O19: Add-ons up to €35M; buy-back approximately €40M | P19: https://en.as.com/en/2020/09/16/soccer/1600251928_757594.html | Q19: High
A20: Óscar Rodríguez | B20: Attacking midfielder | C20: 2020 | D20: Sevilla | E20: Partial sale | F20: 13.5 | G20: 25 | H20: No | I20: No | J20: 25 | K20: No | M20: =F20-IF(K20="Yes",IF(L20="",0,L20),0) -> 13.5 | N20: =IF(G20>0,1,0)+IF(H20="Yes",1,0)+IF(I20="Yes",1,0)+IF(J20>0,1,0) -> 2 | O20: 25% retained according to press reports | P20: https://www.realtotal.de/en/oscar-wechsel-zum-fc-sevilla-perfekt/ | Q20: Medium
A21: Fran García | B21: Left-back | C21: 2021 | D21: Rayo Vallecano | E21: Partial sale | F21: 2 | G21: 50 | H21: Yes | I21: No | K21: Yes | L21: 5 | M21: =F21-IF(K21="Yes",IF(L21="",0,L21),0) -> -3 | N21: =IF(G21>0,1,0)+IF(H21="Yes",1,0)+IF(I21="Yes",1,0)+IF(J21>0,1,0) -> 2 | O21: Rayo bought approximately 50%; buy-back in 2023 | P21: https://www.mundodeportivo.com/futbol/rayo-vallecano/20210713/410516615409/fran-garcia-firma-por-el-rayo-hasta-2025.html | Q21: High
A22: Miguel Gutiérrez | B22: Left-back | C22: 2022 | D22: Girona | E22: Partial sale | F22: 4 | G22: 50 | H22: Yes | I22: Yes | J22: 50 | K22: No | M22: =F22-IF(K22="Yes",IF(L22="",0,L22),0) -> 4 | N22: =IF(G22>0,1,0)+IF(H22="Yes",1,0)+IF(I22="Yes",1,0)+IF(J22>0,1,0) -> 4 | O22: 50% model + buy-back + right of first refusal | P22: https://www.relevo.com/futbol/liga-primera/viaje-miguel-gutierrez-vuelta-20221028182012-nt.html | Q22: High
A23: Mario Gila | B23: Centre-back | C23: 2022 | D23: Lazio | E23: Partial sale | F23: 6 | G23: 50 | H23: No | I23: No | J23: 50 | K23: No | M23: =F23-IF(K23="Yes",IF(L23="",0,L23),0) -> 6 | N23: =IF(G23>0,1,0)+IF(H23="Yes",1,0)+IF(I23="Yes",1,0)+IF(J23>0,1,0) -> 2 | O23: 50% retained, as reported | P23: https://www.mundodeportivo.com/futbol/real-madrid/20220704/1001831949/madrid-saca-buen-pellizco-venta-canterano-serie.html | Q23: Medium
A24: Antonio Blanco | B24: Midfielder | C24: 2023 | D24: Alavés | E24: Partial sale | F24: 4 | G24: 50 | H24: Yes | I24: Yes | J24: 50 | K24: No | M24: =F24-IF(K24="Yes",IF(L24="",0,L24),0) -> 4 | N24: =IF(G24>0,1,0)+IF(H24="Yes",1,0)+IF(I24="Yes",1,0)+IF(J24>0,1,0) -> 4 | O24: Partial structure reported; official statement confirms departure | P24: https://www.realmadrid.com/es-ES/noticias/club/comunicados/comunicado-oficial-antonio-blanco-25-07-2023 | Q24: Medium
A25: Sergio Arribas | B25: Attacking midfielder | C25: 2023 | D25: Almería | E25: Partial sale | F25: 8 | G25: 50 | H25: Yes | I25: Yes | J25: 50 | K25: No | M25: =F25-IF(K25="Yes",IF(L25="",0,L25),0) -> 8 | N25: =IF(G25>0,1,0)+IF(H25="Yes",1,0)+IF(I25="Yes",1,0)+IF(J25>0,1,0) -> 4 | O25: Around €8M for 50% | P25: https://www.relevo.com/futbol/liga-primera/gesto-fichaje-arribas-almeria-contratazo-20230807150940-nt.html | Q25: High
A26: Carlos Dotor | B26: Midfielder | C26: 2023 | D26: Celta de Vigo | E26: Partial sale | F26: 3 | G26: 50 | H26: Yes | I26: Yes | J26: 50 | K26: No | M26: =F26-IF(K26="Yes",IF(L26="",0,L26),0) -> 3 | N26: =IF(G26>0,1,0)+IF(H26="Yes",1,0)+IF(I26="Yes",1,0)+IF(J26>0,1,0) -> 4 | O26: 50% structure reported | P26: https://www.transfermarkt.com/carlos-dotor/transfers/spieler/536293 | Q26: Low
A27: Juanmi Latasa | B27: Forward | C27: 2024 | D27: Real Valladolid | E27: Partial sale | F27: 2.5 | G27: 50 | H27: Yes | I27: Yes | J27: 50 | K27: No | M27: =F27-IF(K27="Yes",IF(L27="",0,L27),0) -> 2.5 | N27: =IF(G27>0,1,0)+IF(H27="Yes",1,0)+IF(I27="Yes",1,0)+IF(J27>0,1,0) -> 4 | O27: Official statement; financial terms reported | P27: https://www.realmadrid.com/es-ES/noticias/club/comunicados/comunicado-oficial-latasa-14-08-2024 | Q27: Medium
A28: Peter Federico | B28: Winger | C28: 2024 | D28: Getafe | E28: Partial sale | F28: 2 | G28: 50 | H28: Yes | I28: Yes | J28: 50 | K28: No | M28: =F28-IF(K28="Yes",IF(L28="",0,L28),0) -> 2 | N28: =IF(G28>0,1,0)+IF(H28="Yes",1,0)+IF(I28="Yes",1,0)+IF(J28>0,1,0) -> 4 | O28: Official statement; 50% reported | P28: https://www.realmadrid.com/es-ES/noticias/club/comunicados/comunicado-oficial-peter-federico-04-07-2024 | Q28: Medium
A29: Marvin Park | B29: Winger/Full-back | C29: 2024 | D29: Las Palmas | E29: Partial sale | F29: 2 | G29: 50 | H29: Yes | I29: Yes | J29: 50 | K29: No | M29: =F29-IF(K29="Yes",IF(L29="",0,L29),0) -> 2 | N29: =IF(G29>0,1,0)+IF(H29="Yes",1,0)+IF(I29="Yes",1,0)+IF(J29>0,1,0) -> 4 | O29: Madrid retains part of the rights, according to the press | P29: https://www.transfermarkt.com/marvin-park/transfers/spieler/568454 | Q29: Low
A30: Rafa Marín | B30: Centre-back | C30: 2024 | D30: Nápoles | E30: Sale with buy-back | F30: 12 | H30: Yes | I30: No | K30: No | M30: =F30-IF(K30="Yes",IF(L30="",0,L30),0) -> 12 | N30: =IF(G30>0,1,0)+IF(H30="Yes",1,0)+IF(I30="Yes",1,0)+IF(J30>0,1,0) -> 1 | O30: Staggered buy-back clauses reported at €25M and €35M | P30: https://www.relevo.com/futbol/mercado-fichajes/rafa-marin-napoles-madrid-queda-20240703234327-nt.html | Q30: High
A31: Álex Jiménez | B31: Right-back | C31: 2024 | D31: AC Milan | E31: Sale with buy-back | F31: 5 | H31: Yes | I31: No | J31: 50 | K31: No | M31: =F31-IF(K31="Yes",IF(L31="",0,L31),0) -> 5 | N31: =IF(G31>0,1,0)+IF(H31="Yes",1,0)+IF(I31="Yes",1,0)+IF(J31>0,1,0) -> 2 | O31: Buy-back clauses reported at €9M and €12M; upside afterward | P31: https://www.relevo.com/futbol/mercado-fichajes/milan-queda-alex-jimenez-20240615114636-nt.html | Q31: High
A32: Nico Paz | B32: Attacking midfielder | C32: 2024 | D32: Como | E32: Partial sale | F32: 6 | G32: 50 | H32: Yes | I32: Yes | J32: 50 | K32: No | M32: =F32-IF(K32="Yes",IF(L32="",0,L32),0) -> 6 | N32: =IF(G32>0,1,0)+IF(H32="Yes",1,0)+IF(I32="Yes",1,0)+IF(J32>0,1,0) -> 4 | O32: First sale for 50%; buy-back and right of first refusal structure | P32: https://www.relevo.com/futbol/mercado-fichajes/real-madrid-vende-nico-cesc-20240821181501-nt.html | Q32: High
A33: Mario Martín | B33: Midfielder | C33: 2025 | D33: Getafe | E33: Partial sale | F33: 6 | G33: 50 | H33: Yes | I33: Yes | J33: 50 | K33: No | M33: =F33-IF(K33="Yes",IF(L33="",0,L33),0) -> 6 | N33: =IF(G33>0,1,0)+IF(H33="Yes",1,0)+IF(I33="Yes",1,0)+IF(J33>0,1,0) -> 4 | O33: Deal reported as a partial sale; approximate figure | P33: https://www.transfermarkt.com/mario-martin/transfers/spieler/709991 | Q33: Low
A34: Miguel Baeza | B34: Attacking midfielder | C34: 2020 | D34: Celta de Vigo | E34: Partial sale | F34: 2.5 | G34: 50 | H34: No | I34: No | J34: 50 | K34: No | M34: =F34-IF(K34="Yes",IF(L34="",0,L34),0) -> 2.5 | N34: =IF(G34>0,1,0)+IF(H34="Yes",1,0)+IF(I34="Yes",1,0)+IF(J34>0,1,0) -> 2 | O34: 50% of rights reported | P34: https://www.transfermarkt.com/miguel-baeza/transfers/spieler/536290 | Q34: Low
A35: Rubén de la Red | B35: Midfielder | C35: 2007 | D35: Getafe | E35: Transfer | F35: 3 | G35: 0 | H35: No | I35: No | J35: 0 | K35: No | L35: 0 | M35: =F35-L35 -> 3 | N35: =IF(H35="Yes",2,0)+IF(I35="Yes",1,0)+IF(G35>0,1,0)+IF(J35>0,1,0) -> 0 | O35: Academy graduate who later established himself in La Liga. | P35: https://www.transfermarkt.com/real-madrid-castilla/transfers/verein/6767/saison_id/2007 | Q35: High
A36: Álvaro Arbeloa | B36: Right-back | C36: 2006 | D36: Deportivo de La Coruña | E36: Transfer | F36: 1.3 | G36: 0 | H36: No | I36: No | J36: 0 | K36: No | L36: 0 | M36: =F36-L36 -> 1.3 | N36: =IF(H36="Yes",2,0)+IF(I36="Yes",1,0)+IF(G36>0,1,0)+IF(J36>0,1,0) -> 0 | O36: Departure from the professional structure; later bought back by Real Madrid. | P36: https://www.transfermarkt.com/real-madrid-castilla/transfers/verein/6767/saison_id/2006 | Q36: High
A37: Diego López | B37: Goalkeeper | C37: 2007 | D37: Villarreal | E37: Transfer | F37: 6 | G37: 0 | H37: No | I37: No | J37: 0 | K37: No | L37: 0 | M37: =F37-L37 -> 6 | N37: =IF(H37="Yes",2,0)+IF(I37="Yes",1,0)+IF(G37>0,1,0)+IF(J37>0,1,0) -> 0 | O37: Developed at the academy; returned to the first team in 2013. | P37: https://www.transfermarkt.com/real-madrid-castilla/transfers/verein/6767/saison_id/2007 | Q37: High
A38: Álvaro Mejía | B38: Centre-back | C38: 2007 | D38: Real Murcia | E38: Transfer | F38: 2 | G38: 0 | H38: No | I38: No | J38: 0 | K38: No | L38: 0 | M38: =F38-L38 -> 2 | N38: =IF(H38="Yes",2,0)+IF(I38="Yes",1,0)+IF(G38>0,1,0)+IF(J38>0,1,0) -> 0 | O38: Graduate of Castilla and the first team. | P38: https://www.transfermarkt.com/real-madrid-castilla/transfers/verein/6767/saison_id/2007 | Q38: Medium
A39: Javier Balboa | B39: Right winger | C39: 2008 | D39: Benfica | E39: Transfer | F39: 4 | G39: 0 | H39: No | I39: No | J39: 0 | K39: No | L39: 0 | M39: =F39-L39 -> 4 | N39: =IF(H39="Yes",2,0)+IF(I39="Yes",1,0)+IF(G39>0,1,0)+IF(J39>0,1,0) -> 0 | O39: International sale from the first team. | P39: https://www.transfermarkt.com/real-madrid-castilla/transfers/verein/6767/saison_id/2008 | Q39: High
A40: Adrián González | B40: Midfielder | C40: 2008 | D40: Getafe | E40: Transfer | F40: 0 | G40: 0 | H40: No | I40: No | J40: 0 | K40: No | L40: 0 | M40: =F40-L40 -> 0 | N40: =IF(H40="Yes",2,0)+IF(I40="Yes",1,0)+IF(G40>0,1,0)+IF(J40>0,1,0) -> 0 | O40: Academy graduate departure to La Liga; amount not publicly verified. | P40: https://www.transfermarkt.com/real-madrid-castilla/transfers/verein/6767/saison_id/2008 | Q40: Medium
...

Sheet Coverage
A1: COVERAGE OF THE EXPANDED RESEARCH
A3: Metric | B3: Value | C3: Interpretation | D3: Source / method | E3: Status | F3: Notes
A4: Total cases | B4: =COUNTA(Cases!A2:A138) -> 137 | C4: Documented professional departures and relevant moves | D4: Transfermarkt by season + press sources from the original file | E4: Complete for the scope | F4: Not equivalent to every youth player who passed through the lower categories.
A5: New cases added | B5: 104 | C5: New rows compared to the previous file | D5: 2006-2026 review | E5: Completed | F5: Includes free transfers, loans, and deals with no public fee.
A6: Sales with fee > 0 | B6: =COUNTIF(Cases!F2:F138,">0") -> 66 | C6: Deals with an identified consideration | D6: Initial fee column | E6: Calculated | F6: Fees may be initial figures and may not include add-ons.
A7: Departures with no public fee | B7: =COUNTIF(Cases!F2:F138,0) -> 71 | C7: Free transfers, loans, or undisclosed amount | D7: Operation type + notes | E7: Calculated | F7: A 0 does not always mean no compensation existed.
A8: High confidence | B8: =COUNTIF(Cases!Q2:Q138,"High") -> 71 | C8: Widely confirmed data | D8: Primary source and press | E8: Calculated | F8: Prioritize these cases for financial analysis.
A9: Medium/low confidence | B9: =COUNTIF(Cases!Q2:Q138,"Medium")+COUNTIF(Cases!Q2:Q138,"Low") -> 66 | C9: Cases requiring additional review | D9: Aggregator source or incomplete data | E9: Review | F9: Do not use as a definitive contractual figure.
A12: Inclusion criteria
A13: 1. Players developed at La Fábrica who reached Castilla, Real Madrid C, or the first team and had a documentable professional departure.
A14: 2. Loans and free departures are also included to avoid bias toward only large sales.
A15: 3. The list is not claimed to be a census of every youth player in history: historical lower-category squads do not have complete public traceability.
A16: 4. Cuando no existe fee público fiable, el campo se deja en 0 y se explica en “Detalle contractual”; no debe interpretarse automáticamente como operación gratuita.
A17: 5. Specific clauses are kept only when there is reasonably consistent public information.

Sheet Summary
A1: REAL MADRID · LA FÁBRICA — EXPANDED ANALYSIS 2006–2026
A2: Base expanded to 137 documented cases: sales, free transfers, loans, and deals with optionality. | J2: Type | K2: No. of cases
J3: Sale with buy-back | K3: =COUNTIF(Cases!E2:E138,"Sale with buy-back") -> 9
A4: Documented cases | B4: =COUNTA(Cases!A2:A138) -> 137 | J4: Partial sale | K4: =COUNTIF(Cases!E2:E138,"Partial sale") -> 13
A5: Cumulative initial fees (€M) | B5: =SUM(Cases!F2:F138) -> 396.9 | J5: Transfer | K5: =COUNTIF(Cases!E2:E138,"Transfer") -> 57
A6: Direct net income (€M) | B6: =SUM(Cases!M2:M138) -> 319.4 | J6: Sale with sell-on | K6: =COUNTIF(Cases!E2:E138,"Sale with sell-on") -> 1
A7: Deals with a buy-back clause | B7: =COUNTIF(Cases!H2:H138,"Yes") -> 21 | J7: End of contract | K7: =COUNTIF(Cases!E2:E138,"End of contract") -> 1
A8: Deals with retained rights | B8: =COUNTIF(Cases!G2:G138,">0") -> 13
A9: Deals with a right of first refusal | B9: =COUNTIF(Cases!I2:I138,"Yes") -> 12
A10: High confidence | B10: =COUNTIF(Cases!Q2:Q138,"High") -> 71 | J10: Position | K10: Fees (€M)
A11: Medium/low confidence | B11: =COUNTIF(Cases!Q2:Q138,"<>Alta") -> 137 | J11: Forward | K11: =SUMIF(Cases!B2:B138,"Forward",Cases!F2:F138) -> 107
J12: Midfielder | K12: =SUMIF(Cases!B2:B138,"Midfielder",Cases!F2:F138) -> 63
J13: Attacking midfielder | K13: =SUMIF(Cases!B2:B138,"Attacking midfielder",Cases!F2:F138) -> 33
A14: Strategic reading | J14: Winger | K14: =SUMIF(Cases!B2:B138,"Winger",Cases!F2:F138) -> 28.2
A15: 1. De recompra clásica a “venta parcial” | B15: Between 2008 and 2016, buy-backs predominate: Granero, Carvajal, and Morata. Since 2021, the model of selling around 50% while retaining upside has become established. | J15: Right-back | K15: =SUMIF(Cases!B2:B138,"Right-back",Cases!F2:F138) -> 51.7
A16: 2. The club monetizes without losing control | B16: The modern pattern combines immediate cash, a buy-back clause, a right of first refusal, and a stake in a future sale. The departure is no longer binary: sale or loan. | J16: Left-back | K16: =SUMIF(Cases!B2:B138,"Left-back",Cases!F2:F138) -> 46.9
A17: 3. The academy works as an options portfolio | B17: Every partially sold academy graduate acts as a financial option: Madrid limits development risk while retaining exposure if the player increases in value. | J17: Centre-back | K17: =SUMIF(Cases!B2:B138,"Centre-back",Cases!F2:F138) -> 35.3
A18: 4. Public information is incomplete | B18: Many official statements only confirm the deal. Fees, percentages, and buy-back prices usually come from the press; that is why each row includes a confidence level.
A19: 5. Paradigmatic cases | B19: Carvajal represents the sporting buy-back; Morata, the buy-back and resale; Mariano, the sell-on arbitrage; Miguel and Arribas, the 50% model; Rafa Marín and Nico Paz, sophisticated optionality.
A39: Scope and caveats
A40: La base cubre salidas profesionales relevantes y documentables desde 2006. No equivale a un censo absoluto de todos los jugadores que pasaron por cualquier categoría juvenil, ya que muchas bajas formativas, rescisiones y acuerdos menores no tienen cifras públicas. Las cifras contractuales deben leerse según la columna “Confianza”.

Sheet Timeline
A1: Year | B1: Player | C1: Destination club | D1: Fee (€M) | E1: Model | F1: Optionality
A2: 2008 | B2: Roberto Soldado | C2: Getafe | D2: 6 | E2: Transfer | F2: =IF(Cases!N2>0,"Yes","No") -> Yes
A3: 2009 | B3: Javi García | C3: Benfica | D3: 7 | E3: Transfer | F3: =IF(Cases!N3>0,"Yes","No") -> No
A4: 2009 | B4: Álvaro Negredo | C4: Almería / Sevilla | D4: 15 | E4: Sale with buy-back | F4: =IF(Cases!N4>0,"Yes","No") -> Yes
A5: 2008 | B5: Esteban Granero | C5: Getafe | D5: 3 | E5: Sale with buy-back | F5: =IF(Cases!N5>0,"Yes","No") -> Yes
A6: 2009 | B6: Dani Parejo | C6: Getafe | D6: 3 | E6: Sale with buy-back | F6: =IF(Cases!N6>0,"Yes","No") -> Yes
A7: 2007 | B7: Borja Valero | C7: Mallorca | D7: 0 | E7: Transfer | F7: =IF(Cases!N7>0,"Yes","No") -> No
A8: 2007 | B8: Juan Mata | C8: Valencia | D8: 0 | E8: End of contract | F8: =IF(Cases!N8>0,"Yes","No") -> No
A9: 2008 | B9: José Callejón | C9: Espanyol | D9: 1.2 | E9: Transfer | F9: =IF(Cases!N9>0,"Yes","No") -> Yes
A10: 2012 | B10: Dani Carvajal | C10: Bayer Leverkusen | D10: 5 | E10: Sale with buy-back | F10: =IF(Cases!N10>0,"Yes","No") -> Yes
A11: 2011 | B11: Pablo Sarabia | C11: Getafe | D11: 3 | E11: Transfer | F11: =IF(Cases!N11>0,"Yes","No") -> Yes
A12: 2012 | B12: Joselu Mato | C12: Hoffenheim | D12: 6 | E12: Transfer | F12: =IF(Cases!N12>0,"Yes","No") -> No
A13: 2014 | B13: Álvaro Morata | C13: Juventus | D13: 20 | E13: Sale with buy-back | F13: =IF(Cases!N13>0,"Yes","No") -> Yes
... A34: 2020 | B34: Miguel Baeza | C34: Celta de Vigo | D34: 2.5 | E34: Partial sale | F34: =IF(Cases!N34>0,"Yes","No") -> Yes

Sheet Glossary
A1: Field | B1: Definition
A2: Initial fee (€M) | B2: Fixed amount reported at the time of departure. Does not always include add-ons, bonuses, or solidarity mechanisms.
A3: Retained rights (%) | B3: Share of the economic asset or of a future sale that, according to the sources, Real Madrid retains.
A4: Buy-back | B4: Public or reported existence of a price/window allowing Madrid to reacquire the player.
A5: Right of first refusal | B5: Right to match a future third-party offer.
A6: Sell-on (%) | B6: Reported stake in a future sale or in the capital gain.
A7: Direct net income (€M) | B7: Initial fee minus buy-back cost when the player returned. Does not include later resales, salaries, or bonuses.
A8: Optionality index | B8: Simple sum of four mechanisms: retained rights, buy-back, right of first refusal, and sell-on. Scale 0-4.
A9: Confidence | B9: High: primary source or several solid sources. Medium: widely reported figure. Low: database or secondary press without contractual confirmation.

Sheet Sources
A1: Player | B1: Main URL | C1: Confidence level | D1: Note
A2: Roberto Soldado | B2: https://www.uefa.com/news-media/news/01cf-0f84e103e15d-07b4863d3d03-1000--soldado-set-to-seal-getafe-switch/ | C2: Medium | D2: Amount reported as up to €6M
A3: Javi García | B3: https://as.com/futbol/2009/07/27/mas_futbol/1248645630_850215.html | C3: Medium | D3: Outright sale
A4: Álvaro Negredo | B4: https://www.relevo.com/futbol/liga-primera/formula-cedidos-funciona-ventas-recompra-20221223100551-nt.html | C4: Medium | D4: Madrid exercised the buy-back before selling to Sevilla
A5: Esteban Granero | B5: https://www.skysports.com/football/news/3814810/getafe-sign-granero | C5: Medium | D5: Bought back a year later
A6: Dani Parejo | B6: https://www.relevo.com/futbol/liga-primera/formula-cedidos-funciona-ventas-recompra-20221223100551-nt.html | C6: Low | D6: Future control rights reported
A7: Borja Valero | B7: https://www.transfermarkt.com/borja-valero/transfers/spieler/40372 | C7: Low | D7: Departure with no significant public fee
A8: Juan Mata | B8: https://www.transfermarkt.com/juan-mata/transfers/spieler/44068 | C8: Medium | D8: Free departure after not renewing
A9: José Callejón | B9: https://www.transfermarkt.com/jose-callejon/transfers/spieler/25927 | C9: Medium | D9: Bought back in 2011
A10: Dani Carvajal | B10: https://www.uefa.com/uefachampionsleague/news/0250-0c5101575c8f-e8cc021f4c61-1000--carvajal-returns-to-madrid-from-leverkusen/ | C10: High | D10: Three buy-back windows; returned the following year
A11: Pablo Sarabia | B11: https://www.transfermarkt.com/pablo-sarabia/transfers/spieler/74230 | C11: Low | D11: Buy-back clause reported
A12: Joselu Mato | B12: https://www.transfermarkt.com/joselu/transfers/spieler/81999 | C12: Medium | D12: Outright sale; returned years later on loan from another club
... A55: Transfermarkt Castilla season 2026/27 | B55: https://www.transfermarkt.com/real-madrid-castilla/transfers/verein/6767/saison_id/2026 | C55: Medium | D55: Season-by-season aggregator page for Castilla departures

Sheet By season
A1: Year | B1: No. of cases | C1: Fees identified (€M) | D1: With fee | E1: No fee/loan | F1: High confidence
A2: 2006 | B2: =COUNTIF(Cases!C:C,A2) -> 4 | C2: =SUMIF(Cases!C:C,A2,Cases!F:F) -> 1.7 | D2: =COUNTIFS(Cases!C:C,A2,Cases!F:F,">0") -> 2 | E2: =COUNTIFS(Cases!C:C,A2,Cases!F:F,0) -> 2 | F2: =COUNTIFS(Cases!C:C,A2,Cases!Q:Q,"High") -> 2
A3: 2007 | B3: =COUNTIF(Cases!C:C,A3) -> 6 | C3: =SUMIF(Cases!C:C,A3,Cases!F:F) -> 11 | D3: =COUNTIFS(Cases!C:C,A3,Cases!F:F,">0") -> 3 | E3: =COUNTIFS(Cases!C:C,A3,Cases!F:F,0) -> 3 | F3: =COUNTIFS(Cases!C:C,A3,Cases!Q:Q,"High") -> 2
A4: 2008 | B4: =COUNTIF(Cases!C:C,A4) -> 6 | C4: =SUMIF(Cases!C:C,A4,Cases!F:F) -> 14.2 | D4: =COUNTIFS(Cases!C:C,A4,Cases!F:F,">0") -> 4 | E4: =COUNTIFS(Cases!C:C,A4,Cases!F:F,0) -> 2 | F4: =COUNTIFS(Cases!C:C,A4,Cases!Q:Q,"High") -> 1
A5: 2009 | B5: =COUNTIF(Cases!C:C,A5) -> 6 | C5: =SUMIF(Cases!C:C,A5,Cases!F:F) -> 30 | D5: =COUNTIFS(Cases!C:C,A5,Cases!F:F,">0") -> 5 | E5: =COUNTIFS(Cases!C:C,A5,Cases!F:F,0) -> 1 | F5: =COUNTIFS(Cases!C:C,A5,Cases!Q:Q,"High") -> 3
A6: 2010 | B6: =COUNTIF(Cases!C:C,A6) -> 4 | C6: =SUMIF(Cases!C:C,A6,Cases!F:F) -> 8.4 | D6: =COUNTIFS(Cases!C:C,A6,Cases!F:F,">0") -> 2 | E6: =COUNTIFS(Cases!C:C,A6,Cases!F:F,0) -> 2 | F6: =COUNTIFS(Cases!C:C,A6,Cases!Q:Q,"High") -> 2
A7: 2011 | B7: =COUNTIF(Cases!C:C,A7) -> 9 | C7: =SUMIF(Cases!C:C,A7,Cases!F:F) -> 4 | D7: =COUNTIFS(Cases!C:C,A7,Cases!F:F,">0") -> 2 | E7: =COUNTIFS(Cases!C:C,A7,Cases!F:F,0) -> 7 | F7: =COUNTIFS(Cases!C:C,A7,Cases!Q:Q,"High") -> 2
A8: 2012 | B8: =COUNTIF(Cases!C:C,A8) -> 4 | C8: =SUMIF(Cases!C:C,A8,Cases!F:F) -> 17 | D8: =COUNTIFS(Cases!C:C,A8,Cases!F:F,">0") -> 3 | E8: =COUNTIFS(Cases!C:C,A8,Cases!F:F,0) -> 1 | F8: =COUNTIFS(Cases!C:C,A8,Cases!Q:Q,"High") -> 2
A9: 2013 | B9: =COUNTIF(Cases!C:C,A9) -> 7 | C9: =SUMIF(Cases!C:C,A9,Cases!F:F) -> 0.5 | D9: =COUNTIFS(Cases!C:C,A9,Cases!F:F,">0") -> 1 | E9: =COUNTIFS(Cases!C:C,A9,Cases!F:F,0) -> 6 | F9: =COUNTIFS(Cases!C:C,A9,Cases!Q:Q,"High") -> 3
A10: 2014 | B10: =COUNTIF(Cases!C:C,A10) -> 3 | C10: =SUMIF(Cases!C:C,A10,Cases!F:F) -> 20.5 | D10: =COUNTIFS(Cases!C:C,A10,Cases!F:F,">0") -> 2 | E10: =COUNTIFS(Cases!C:C,A10,Cases!F:F,0) -> 1 | F10: =COUNTIFS(Cases!C:C,A10,Cases!Q:Q,"High") -> 2
A11: 2015 | B11: =COUNTIF(Cases!C:C,A11) -> 1 | C11: =SUMIF(Cases!C:C,A11,Cases!F:F) -> 0.5 | D11: =COUNTIFS(Cases!C:C,A11,Cases!F:F,">0") -> 1 | E11: =COUNTIFS(Cases!C:C,A11,Cases!F:F,0) -> 0 | F11: =COUNTIFS(Cases!C:C,A11,Cases!Q:Q,"High") -> 1
A12: 2016 | B12: =COUNTIF(Cases!C:C,A12) -> 4 | C12: =SUMIF(Cases!C:C,A12,Cases!F:F) -> 34.5 | D12: =COUNTIFS(Cases!C:C,A12,Cases!F:F,">0") -> 4 | E12: =COUNTIFS(Cases!C:C,A12,Cases!F:F,0) -> 0 | F12: =COUNTIFS(Cases!C:C,A12,Cases!Q:Q,"High") -> 4
A13: 2017 | B13: =COUNTIF(Cases!C:C,A13) -> 5 | C13: =SUMIF(Cases!C:C,A13,Cases!F:F) -> 17 | D13: =COUNTIFS(Cases!C:C,A13,Cases!F:F,">0") -> 3 | E13: =COUNTIFS(Cases!C:C,A13,Cases!F:F,0) -> 2 | F13: =COUNTIFS(Cases!C:C,A13,Cases!Q:Q,"High") -> 3
... A22: 2026 | B22: =COUNTIF(Cases!C:C,A22) -> 1 | C22: =SUMIF(Cases!C:C,A22,Cases!F:F) -> 0 | D22: =COUNTIFS(Cases!C:C,A22,Cases!F:F,">0") -> 0 | E22: =COUNTIFS(Cases!C:C,A22,Cases!F:F,0) -> 1 | F22: =COUNTIFS(Cases!C:C,A22,Cases!Q:Q,"High") -> 0
